Workbook

Sheet 00_README
A1: GemPundit Magento Catalog Automation Workbook
A2: Use this workbook as the normalized reference structure for loose gemstone catalogue enrichment, validation, and Magento import generation.
A4: Section | B4: Description
A5: Purpose | B5: Convert raw vendor/product catalogue rows into validated Magento-ready rows using reference sheets instead of manual copy-paste madness.
A6: Primary input | B6: 01_Input_Raw_Products. Paste raw product rows here or let the Python CLI read a separate raw workbook.
A7: Primary output | B7: 02_Output_Magento_Import. Formula view for business users. The Python code also generates a hard-value Magento import file.
A8: Manual review | B8: 03_Validation_Report highlights missing SKU, missing lookup, missing tax/classification/URL, price problems, duplicate SKUs, and unresolved mappings.
A9: Reference masters | B9: 10-19 sheets hold gemstone, colour, certification, shipping, calibration, astro, physical property, and naming rules.
A10: Admin/config | B10: 20_Admin_Config and 21_Field_Map define defaults and field-level source logic.
A11: Operational rule | B11: Do not edit output columns manually. Fix raw input or master lookup sheets, then regenerate.
A12: Version | B12: v1.0 generated on 2026-04-27
A15: Old Workbook → New Structure | B15: Migration intent
A16: Valid Values | B16: Split into 18_Valid_Values plus dropdown validations on input/admin sheets.
A17: Gem_Type | B17: Normalize into 10_Master_Gem_Types as the main source of truth.
... A26: gemstone2_wise | B26: Move to 11_Master_Gemstone2 as defaults only, not final truth.

Sheet 01_Input_Raw_Products
A1: 01_Input_Raw_Products
A2: Paste/import raw catalogue data here. Yellow columns are manual input. Red/orange columns should be corrected before automation.
A3: row_id | B3: sku | C3: vendor_sku | D3: gemstone_raw | E3: gemstone2_raw | F3: gem_type_raw | G3: origin_raw | H3: treatment_raw | I3: shape_raw | J3: cutting_style_raw | K3: certificate_colour_raw | L3: certification_lab | M3: product_type | N3: carat_weight | O3: ratti_weight | P3: dimensions | Q3: price | R3: special_price | S3: shipping_days | T3: stock_status | U3: vendor_id | V3: certificate_no | W3: image_folder | X3: manual_url_key | Y3: notes
A4: 1 | B4: GP-RUBY-0001 | C4: VND-RB-001 | D4: Ruby | E4: Mozambique Ruby | F4: Mozambique Ruby | G4: Mozambique | H4: Heated | I4: Oval | J4: Faceted | K4: Vivid Red | L4: IGI Certified | M4: Single Stone | N4: 2.15 | P4: 8.1 x 6.2 x 3.4 | Q4: 125000 | R4: 115000 | S4: 3 | T4: In Stock | U4: V001 | V4: IGI12345 | W4: /images/ruby/ | Y4: Sample raw row
A5: 2 | B5: GP-BS-0002 | C5: VND-BS-002 | D5: Blue Sapphire | E5: Ceylon Blue Sapphire | F5: Royal Blue Sapphire | G5: Sri Lanka | H5: Heated | I5: Cushion | J5: Faceted | K5: Royal Blue | L5: GRS Certified | M5: Single Stone | O5: 3.3 | P5: 7.8 x 6.9 x 4.0 | Q5: 240000 | S5: 7 | T5: In Stock | U5: V002 | V5: GRS9988 | W5: /images/blue-sapphire/ | Y5: Ratti given; carat auto-derived
A6: =IF(B6<>"",ROW()-2,"") -> 0 | B6: GP-EM-0003 | C6: VND-EM-003 | D6: Emerald | E6: Zambian Emerald | F6: Minor Oil Emerald | G6: Zambia | H6: Minor Oil | I6: Emerald Cut | J6: Faceted | K6: Green | L6: AIGS Certified | M6: Single Stone | N6: 1.55 | P6: 7.0 x 5.1 x 3.2 | Q6: 98000 | R6: 92000 | S6: 14 | T6: In Stock | U6: V003 | V6: AIGS777 | W6: /images/emerald/ | Y6: Check shipping rule
A7: =IF(B7<>"",ROW()-2,"") -> 0
A8: =IF(B8<>"",ROW()-2,"") -> 0
A9: =IF(B9<>"",ROW()-2,"") -> 0
A10: =IF(B10<>"",ROW()-2,"") -> 0
A11: =IF(B11<>"",ROW()-2,"") -> 0
A12: =IF(B12<>"",ROW()-2,"") -> 0
A13: =IF(B13<>"",ROW()-2,"") -> 0
A14: =IF(B14<>"",ROW()-2,"") -> 0
A15: =IF(B15<>"",ROW()-2,"") -> 0
A16: =IF(B16<>"",ROW()-2,"") -> 0
A17: =IF(B17<>"",ROW()-2,"") -> 0
A18: =IF(B18<>"",ROW()-2,"") -> 0
... A502: =IF(B502<>"",ROW()-2,"") -> 0

Sheet 02_Output_Magento_Import
A1: 02_Output_Magento_Import
A2: Formula preview of Magento import rows. The Python CLI writes a clean hard-value import workbook for upload.
A3: attribute_set_id | B3: product_type | C3: sku | D3: name | E3: meta_title | F3: url_key | G3: sku_for_vendor_product | H3: treatment | I3: carat_weight | J3: classification | K3: cutting_style | L3: dimensions | M3: j_colour | N3: name2 | O3: offers | P3: vendor_id | Q3: weight_ratti | R3: shipping_days | S3: hsn_code | T3: price | U3: special_price | V3: weight_carats | W3: origin | X3: gem_composition | Y3: tax_class_id | Z3: certification_sticker | AA3: dispatch_days | AB3: astro_status | AC3: product_visibility | AD3: validation_status | AE3: validation_notes
A4: =IF('01_Input_Raw_Products'!B4<>"",20,"") -> 0 | B4: {=IF('01_Input_Raw_Products'!M4<>"",'01_Input_Raw_Products'!M4,IFERROR(_xlfn.XLOOKUP('01_Input_Raw_Products'!F4,'10_Master_Gem_Types'!A:A,'10_Master_Gem_Types'!K:K),""))} -> 0 | C4: ='01_Input_Raw_Products'!B4 -> 0 | D4: =IF(C4="","",TEXT(I4,"0.00")&" Ct "&IF('01_Input_Raw_Products'!F4<>"",'01_Input_Raw_Products'!F4,'01_Input_Raw_Products'!D4)&" "&'01_Input_Raw_Products'!I4) -> 0 | E4: =IF(C4="","",D4&" | GemPundit") -> 0 | F4: {=IF('01_Input_Raw_Products'!X4<>"",'01_Input_Raw_Products'!X4,IFERROR(_xlfn.XLOOKUP('01_Input_Raw_Products'!F4,'10_Master_Gem_Types'!A:A,'10_Master_Gem_Types'!O:O),LOWER(SUBSTITUTE(IF('01_Input_Raw_Products'!F4<>"",'01_Input_Raw_Products'!F4,'01_Input_Raw_Products'!D4)," ","-"))))} -> 0 | G4: ='01_Input_Raw_Products'!C4 -> 0 | H4: {=IF('01_Input_Raw_Products'!H4<>"",'01_Input_Raw_Products'!H4,IFERROR(_xlfn.XLOOKUP('01_Input_Raw_Products'!F4,'10_Master_Gem_Types'!A:A,'10_Master_Gem_Types'!D:D),""))} -> 0 | I4: =IF('01_Input_Raw_Products'!N4<>"",'01_Input_Raw_Products'!N4,IF('01_Input_Raw_Products'!O4<>"",'01_Input_Raw_Products'!O4*0.91,"")) -> 0 | J4: {=IFERROR(_xlfn.XLOOKUP('01_Input_Raw_Products'!F4,'10_Master_Gem_Types'!A:A,'10_Master_Gem_Types'!N:N),"")} -> 0 | K4: {=IF('01_Input_Raw_Products'!J4<>"",'01_Input_Raw_Products'!J4,IFERROR(_xlfn.XLOOKUP('01_Input_Raw_Products'!F4,'10_Master_Gem_Types'!A:A,'10_Master_Gem_Types'!E:E),""))} -> 0 | L4: ='01_Input_Raw_Products'!P4 -> 0 | M4: {=IFERROR(_xlfn.XLOOKUP('01_Input_Raw_Products'!K4,'12_Color_Mapping'!A:A,'12_Color_Mapping'!B:B),IFERROR(_xlfn.XLOOKUP('01_Input_Raw_Products'!F4,'10_Master_Gem_Types'!A:A,'10_Master_Gem_Types'!F:F),""))} -> 0 | N4: =IF(C4="","",IF('01_Input_Raw_Products'!F4<>"",'01_Input_Raw_Products'!F4,'01_Input_Raw_Products'!D4)) -> 0 | O4: =IF(C4="","","Catalog Automation") -> 0 | P4: ='01_Input_Raw_Products'!U4 -> 0 | Q4: =IF('01_Input_Raw_Products'!O4<>"",'01_Input_Raw_Products'!O4,IF('01_Input_Raw_Products'!N4<>"",'01_Input_Raw_Products'!N4*1.1,"")) -> 0 | R4: ='01_Input_Raw_Products'!S4 -> 0 | S4: {=IFERROR(_xlfn.XLOOKUP('01_Input_Raw_Products'!F4,'10_Master_Gem_Types'!A:A,'10_Master_Gem_Types'!H:H),"")} -> 0 | T4: ='01_Input_Raw_Products'!Q4 -> 0 | U4: ='01_Input_Raw_Products'!R4 -> 0 | V4: =I4 -> 0 | W4: {=IF('01_Input_Raw_Products'!G4<>"",'01_Input_Raw_Products'!G4,IFERROR(_xlfn.XLOOKUP('01_Input_Raw_Products'!F4,'10_Master_Gem_Types'!A:A,'10_Master_Gem_Types'!L:L),""))} -> 0 | X4: {=IFERROR(_xlfn.XLOOKUP('01_Input_Raw_Products'!F4,'10_Master_Gem_Types'!A:A,'10_Master_Gem_Types'!J:J),"")} -> 0 | Y4: {=IFERROR(_xlfn.XLOOKUP('01_Input_Raw_Products'!F4,'10_Master_Gem_Types'!A:A,'10_Master_Gem_Types'!I:I),"")} -> 0 | Z4: {=IFERROR(_xlfn.XLOOKUP('01_Input_Raw_Products'!L4,'13_Certification_Stickers'!A:A,'13_Certification_Stickers'!C:C),"")} -> 0 | AA4: {=IFERROR(_xlfn.XLOOKUP('01_Input_Raw_Products'!S4,'14_Shipping_Rules'!A:A,'14_Shipping_Rules'!B:B),"")} -> 0 | AB4: {=IFERROR(_xlfn.XLOOKUP('01_Input_Raw_Products'!D4,'16_Astro_Flags'!A:A,'16_Astro_Flags'!B:B),"")} -> 0 | AC4: =IF(C4="","","Catalog, Search") -> 0 | AD4: =IF(C4="","",IF(OR(F4="",J4="",M4="",S4="",Y4=""),"Manual Review","Ready")) -> 0 | AE4: =IF(C4="","",TEXTJOIN("; ",TRUE,IF(F4="","Missing url_key",""),IF(J4="","Missing classification",""),IF(M4="","Missing j_colour",""),IF(S4="","Missing hsn_code",""),IF(Y4="","Missing tax_class_id",""))) -> 0
A5: =IF('01_Input_Raw_Products'!B5<>"",20,"") -> 0 | B5: {=IF('01_Input_Raw_Products'!M5<>"",'01_Input_Raw_Products'!M5,IFERROR(_xlfn.XLOOKUP('01_Input_Raw_Products'!F5,'10_Master_Gem_Types'!A:A,'10_Master_Gem_Types'!K:K),""))} -> 0 | C5: ='01_Input_Raw_Products'!B5 -> 0 | D5: =IF(C5="","",TEXT(I5,"0.00")&" Ct "&IF('01_Input_Raw_Products'!F5<>"",'01_Input_Raw_Products'!F5,'01_Input_Raw_Products'!D5)&" "&'01_Input_Raw_Products'!I5) -> 0 | E5: =IF(C5="","",D5&" | GemPundit") -> 0 | F5: {=IF('01_Input_Raw_Products'!X5<>"",'01_Input_Raw_Products'!X5,IFERROR(_xlfn.XLOOKUP('01_Input_Raw_Products'!F5,'10_Master_Gem_Types'!A:A,'10_Master_Gem_Types'!O:O),LOWER(SUBSTITUTE(IF('01_Input_Raw_Products'!F5<>"",'01_Input_Raw_Products'!F5,'01_Input_Raw_Products'!D5)," ","-"))))} -> 0 | G5: ='01_Input_Raw_Products'!C5 -> 0 | H5: {=IF('01_Input_Raw_Products'!H5<>"",'01_Input_Raw_Products'!H5,IFERROR(_xlfn.XLOOKUP('01_Input_Raw_Products'!F5,'10_Master_Gem_Types'!A:A,'10_Master_Gem_Types'!D:D),""))} -> 0 | I5: =IF('01_Input_Raw_Products'!N5<>"",'01_Input_Raw_Products'!N5,IF('01_Input_Raw_Products'!O5<>"",'01_Input_Raw_Products'!O5*0.91,"")) -> 0 | J5: {=IFERROR(_xlfn.XLOOKUP('01_Input_Raw_Products'!F5,'10_Master_Gem_Types'!A:A,'10_Master_Gem_Types'!N:N),"")} -> 0 | K5: {=IF('01_Input_Raw_Products'!J5<>"",'01_Input_Raw_Products'!J5,IFERROR(_xlfn.XLOOKUP('01_Input_Raw_Products'!F5,'10_Master_Gem_Types'!A:A,'10_Master_Gem_Types'!E:E),""))} -> 0 | L5: ='01_Input_Raw_Products'!P5 -> 0 | M5: {=IFERROR(_xlfn.XLOOKUP('01_Input_Raw_Products'!K5,'12_Color_Mapping'!A:A,'12_Color_Mapping'!B:B),IFERROR(_xlfn.XLOOKUP('01_Input_Raw_Products'!F5,'10_Master_Gem_Types'!A:A,'10_Master_Gem_Types'!F:F),""))} -> 0 | N5: =IF(C5="","",IF('01_Input_Raw_Products'!F5<>"",'01_Input_Raw_Products'!F5,'01_Input_Raw_Products'!D5)) -> 0 | O5: =IF(C5="","","Catalog Automation") -> 0 | P5: ='01_Input_Raw_Products'!U5 -> 0 | Q5: =IF('01_Input_Raw_Products'!O5<>"",'01_Input_Raw_Products'!O5,IF('01_Input_Raw_Products'!N5<>"",'01_Input_Raw_Products'!N5*1.1,"")) -> 0 | R5: ='01_Input_Raw_Products'!S5 -> 0 | S5: {=IFERROR(_xlfn.XLOOKUP('01_Input_Raw_Products'!F5,'10_Master_Gem_Types'!A:A,'10_Master_Gem_Types'!H:H),"")} -> 0 | T5: ='01_Input_Raw_Products'!Q5 -> 0 | U5: ='01_Input_Raw_Products'!R5 -> 0 | V5: =I5 -> 0 | W5: {=IF('01_Input_Raw_Products'!G5<>"",'01_Input_Raw_Products'!G5,IFERROR(_xlfn.XLOOKUP('01_Input_Raw_Products'!F5,'10_Master_Gem_Types'!A:A,'10_Master_Gem_Types'!L:L),""))} -> 0 | X5: {=IFERROR(_xlfn.XLOOKUP('01_Input_Raw_Products'!F5,'10_Master_Gem_Types'!A:A,'10_Master_Gem_Types'!J:J),"")} -> 0 | Y5: {=IFERROR(_xlfn.XLOOKUP('01_Input_Raw_Products'!F5,'10_Master_Gem_Types'!A:A,'10_Master_Gem_Types'!I:I),"")} -> 0 | Z5: {=IFERROR(_xlfn.XLOOKUP('01_Input_Raw_Products'!L5,'13_Certification_Stickers'!A:A,'13_Certification_Stickers'!C:C),"")} -> 0 | AA5: {=IFERROR(_xlfn.XLOOKUP('01_Input_Raw_Products'!S5,'14_Shipping_Rules'!A:A,'14_Shipping_Rules'!B:B),"")} -> 0 | AB5: {=IFERROR(_xlfn.XLOOKUP('01_Input_Raw_Products'!D5,'16_Astro_Flags'!A:A,'16_Astro_Flags'!B:B),"")} -> 0 | AC5: =IF(C5="","","Catalog, Search") -> 0 | AD5: =IF(C5="","",IF(OR(F5="",J5="",M5="",S5="",Y5=""),"Manual Review","Ready")) -> 0 | AE5: =IF(C5="","",TEXTJOIN("; ",TRUE,IF(F5="","Missing url_key",""),IF(J5="","Missing classification",""),IF(M5="","Missing j_colour",""),IF(S5="","Missing hsn_code",""),IF(Y5="","Missing tax_class_id",""))) -> 0
A6: =IF('01_Input_Raw_Products'!B6<>"",20,"") -> 0 | B6: {=IF('01_Input_Raw_Products'!M6<>"",'01_Input_Raw_Products'!M6,IFERROR(_xlfn.XLOOKUP('01_Input_Raw_Products'!F6,'10_Master_Gem_Types'!A:A,'10_Master_Gem_Types'!K:K),""))} -> 0 | C6: ='01_Input_Raw_Products'!B6 -> 0 | D6: =IF(C6="","",TEXT(I6,"0.00")&" Ct "&IF('01_Input_Raw_Products'!F6<>"",'01_Input_Raw_Products'!F6,'01_Input_Raw_Products'!D6)&" "&'01_Input_Raw_Products'!I6) -> 0 | E6: =IF(C6="","",D6&" | GemPundit") -> 0 | F6: {=IF('01_Input_Raw_Products'!X6<>"",'01_Input_Raw_Products'!X6,IFERROR(_xlfn.XLOOKUP('01_Input_Raw_Products'!F6,'10_Master_Gem_Types'!A:A,'10_Master_Gem_Types'!O:O),LOWER(SUBSTITUTE(IF('01_Input_Raw_Products'!F6<>"",'01_Input_Raw_Products'!F6,'01_Input_Raw_Products'!D6)," ","-"))))} -> 0 | G6: ='01_Input_Raw_Products'!C6 -> 0 | H6: {=IF('01_Input_Raw_Products'!H6<>"",'01_Input_Raw_Products'!H6,IFERROR(_xlfn.XLOOKUP('01_Input_Raw_Products'!F6,'10_Master_Gem_Types'!A:A,'10_Master_Gem_Types'!D:D),""))} -> 0 | I6: =IF('01_Input_Raw_Products'!N6<>"",'01_Input_Raw_Products'!N6,IF('01_Input_Raw_Products'!O6<>"",'01_Input_Raw_Products'!O6*0.91,"")) -> 0 | J6: {=IFERROR(_xlfn.XLOOKUP('01_Input_Raw_Products'!F6,'10_Master_Gem_Types'!A:A,'10_Master_Gem_Types'!N:N),"")} -> 0 | K6: {=IF('01_Input_Raw_Products'!J6<>"",'01_Input_Raw_Products'!J6,IFERROR(_xlfn.XLOOKUP('01_Input_Raw_Products'!F6,'10_Master_Gem_Types'!A:A,'10_Master_Gem_Types'!E:E),""))} -> 0 | L6: ='01_Input_Raw_Products'!P6 -> 0 | M6: {=IFERROR(_xlfn.XLOOKUP('01_Input_Raw_Products'!K6,'12_Color_Mapping'!A:A,'12_Color_Mapping'!B:B),IFERROR(_xlfn.XLOOKUP('01_Input_Raw_Products'!F6,'10_Master_Gem_Types'!A:A,'10_Master_Gem_Types'!F:F),""))} -> 0 | N6: =IF(C6="","",IF('01_Input_Raw_Products'!F6<>"",'01_Input_Raw_Products'!F6,'01_Input_Raw_Products'!D6)) -> 0 | O6: =IF(C6="","","Catalog Automation") -> 0 | P6: ='01_Input_Raw_Products'!U6 -> 0 | Q6: =IF('01_Input_Raw_Products'!O6<>"",'01_Input_Raw_Products'!O6,IF('01_Input_Raw_Products'!N6<>"",'01_Input_Raw_Products'!N6*1.1,"")) -> 0 | R6: ='01_Input_Raw_Products'!S6 -> 0 | S6: {=IFERROR(_xlfn.XLOOKUP('01_Input_Raw_Products'!F6,'10_Master_Gem_Types'!A:A,'10_Master_Gem_Types'!H:H),"")} -> 0 | T6: ='01_Input_Raw_Products'!Q6 -> 0 | U6: ='01_Input_Raw_Products'!R6 -> 0 | V6: =I6 -> 0 | W6: {=IF('01_Input_Raw_Products'!G6<>"",'01_Input_Raw_Products'!G6,IFERROR(_xlfn.XLOOKUP('01_Input_Raw_Products'!F6,'10_Master_Gem_Types'!A:A,'10_Master_Gem_Types'!L:L),""))} -> 0 | X6: {=IFERROR(_xlfn.XLOOKUP('01_Input_Raw_Products'!F6,'10_Master_Gem_Types'!A:A,'10_Master_Gem_Types'!J:J),"")} -> 0 | Y6: {=IFERROR(_xlfn.XLOOKUP('01_Input_Raw_Products'!F6,'10_Master_Gem_Types'!A:A,'10_Master_Gem_Types'!I:I),"")} -> 0 | Z6: {=IFERROR(_xlfn.XLOOKUP('01_Input_Raw_Products'!L6,'13_Certification_Stickers'!A:A,'13_Certification_Stickers'!C:C),"")} -> 0 | AA6: {=IFERROR(_xlfn.XLOOKUP('01_Input_Raw_Products'!S6,'14_Shipping_Rules'!A:A,'14_Shipping_Rules'!B:B),"")} -> 0 | AB6: {=IFERROR(_xlfn.XLOOKUP('01_Input_Raw_Products'!D6,'16_Astro_Flags'!A:A,'16_Astro_Flags'!B:B),"")} -> 0 | AC6: =IF(C6="","","Catalog, Search") -> 0 | AD6: =IF(C6="","",IF(OR(F6="",J6="",M6="",S6="",Y6=""),"Manual Review","Ready")) -> 0 | AE6: =IF(C6="","",TEXTJOIN("; ",TRUE,IF(F6="","Missing url_key",""),IF(J6="","Missing classification",""),IF(M6="","Missing j_colour",""),IF(S6="","Missing hsn_code",""),IF(Y6="","Missing tax_class_id",""))) -> 0
A7: =IF('01_Input_Raw_Products'!B7<>"",20,"") -> 0 | B7: {=IF('01_Input_Raw_Products'!M7<>"",'01_Input_Raw_Products'!M7,IFERROR(_xlfn.XLOOKUP('01_Input_Raw_Products'!F7,'10_Master_Gem_Types'!A:A,'10_Master_Gem_Types'!K:K),""))} -> 0 | C7: ='01_Input_Raw_Products'!B7 -> 0 | D7: =IF(C7="","",TEXT(I7,"0.00")&" Ct "&IF('01_Input_Raw_Products'!F7<>"",'01_Input_Raw_Products'!F7,'01_Input_Raw_Products'!D7)&" "&'01_Input_Raw_Products'!I7) -> 0 | E7: =IF(C7="","",D7&" | GemPundit") -> 0 | F7: {=IF('01_Input_Raw_Products'!X7<>"",'01_Input_Raw_Products'!X7,IFERROR(_xlfn.XLOOKUP('01_Input_Raw_Products'!F7,'10_Master_Gem_Types'!A:A,'10_Master_Gem_Types'!O:O),LOWER(SUBSTITUTE(IF('01_Input_Raw_Products'!F7<>"",'01_Input_Raw_Products'!F7,'01_Input_Raw_Products'!D7)," ","-"))))} -> 0 | G7: ='01_Input_Raw_Products'!C7 -> 0 | H7: {=IF('01_Input_Raw_Products'!H7<>"",'01_Input_Raw_Products'!H7,IFERROR(_xlfn.XLOOKUP('01_Input_Raw_Products'!F7,'10_Master_Gem_Types'!A:A,'10_Master_Gem_Types'!D:D),""))} -> 0 | I7: =IF('01_Input_Raw_Products'!N7<>"",'01_Input_Raw_Products'!N7,IF('01_Input_Raw_Products'!O7<>"",'01_Input_Raw_Products'!O7*0.91,"")) -> 0 | J7: {=IFERROR(_xlfn.XLOOKUP('01_Input_Raw_Products'!F7,'10_Master_Gem_Types'!A:A,'10_Master_Gem_Types'!N:N),"")} -> 0 | K7: {=IF('01_Input_Raw_Products'!J7<>"",'01_Input_Raw_Products'!J7,IFERROR(_xlfn.XLOOKUP('01_Input_Raw_Products'!F7,'10_Master_Gem_Types'!A:A,'10_Master_Gem_Types'!E:E),""))} -> 0 | L7: ='01_Input_Raw_Products'!P7 -> 0 | M7: {=IFERROR(_xlfn.XLOOKUP('01_Input_Raw_Products'!K7,'12_Color_Mapping'!A:A,'12_Color_Mapping'!B:B),IFERROR(_xlfn.XLOOKUP('01_Input_Raw_Products'!F7,'10_Master_Gem_Types'!A:A,'10_Master_Gem_Types'!F:F),""))} -> 0 | N7: =IF(C7="","",IF('01_Input_Raw_Products'!F7<>"",'01_Input_Raw_Products'!F7,'01_Input_Raw_Products'!D7)) -> 0 | O7: =IF(C7="","","Catalog Automation") -> 0 | P7: ='01_Input_Raw_Products'!U7 -> 0 | Q7: =IF('01_Input_Raw_Products'!O7<>"",'01_Input_Raw_Products'!O7,IF('01_Input_Raw_Products'!N7<>"",'01_Input_Raw_Products'!N7*1.1,"")) -> 0 | R7: ='01_Input_Raw_Products'!S7 -> 0 | S7: {=IFERROR(_xlfn.XLOOKUP('01_Input_Raw_Products'!F7,'10_Master_Gem_Types'!A:A,'10_Master_Gem_Types'!H:H),"")} -> 0 | T7: ='01_Input_Raw_Products'!Q7 -> 0 | U7: ='01_Input_Raw_Products'!R7 -> 0 | V7: =I7 -> 0 | W7: {=IF('01_Input_Raw_Products'!G7<>"",'01_Input_Raw_Products'!G7,IFERROR(_xlfn.XLOOKUP('01_Input_Raw_Products'!F7,'10_Master_Gem_Types'!A:A,'10_Master_Gem_Types'!L:L),""))} -> 0 | X7: {=IFERROR(_xlfn.XLOOKUP('01_Input_Raw_Products'!F7,'10_Master_Gem_Types'!A:A,'10_Master_Gem_Types'!J:J),"")} -> 0 | Y7: {=IFERROR(_xlfn.XLOOKUP('01_Input_Raw_Products'!F7,'10_Master_Gem_Types'!A:A,'10_Master_Gem_Types'!I:I),"")} -> 0 | Z7: {=IFERROR(_xlfn.XLOOKUP('01_Input_Raw_Products'!L7,'13_Certification_Stickers'!A:A,'13_Certification_Stickers'!C:C),"")} -> 0 | AA7: {=IFERROR(_xlfn.XLOOKUP('01_Input_Raw_Products'!S7,'14_Shipping_Rules'!A:A,'14_Shipping_Rules'!B:B),"")} -> 0 | AB7: {=IFERROR(_xlfn.XLOOKUP('01_Input_Raw_Products'!D7,'16_Astro_Flags'!A:A,'16_Astro_Flags'!B:B),"")} -> 0 | AC7: =IF(C7="","","Catalog, Search") -> 0 | AD7: =IF(C7="","",IF(OR(F7="",J7="",M7="",S7="",Y7=""),"Manual Review","Ready")) -> 0 | AE7: =IF(C7="","",TEXTJOIN("; ",TRUE,IF(F7="","Missing url_key",""),IF(J7="","Missing classification",""),IF(M7="","Missing j_colour",""),IF(S7="","Missing hsn_code",""),IF(Y7="","Missing tax_class_id",""))) -> 0
A8: =IF('01_Input_Raw_Products'!B8<>"",20,"") -> 0 | B8: {=IF('01_Input_Raw_Products'!M8<>"",'01_Input_Raw_Products'!M8,IFERROR(_xlfn.XLOOKUP('01_Input_Raw_Products'!F8,'10_Master_Gem_Types'!A:A,'10_Master_Gem_Types'!K:K),""))} -> 0 | C8: ='01_Input_Raw_Products'!B8 -> 0 | D8: =IF(C8="","",TEXT(I8,"0.00")&" Ct "&IF('01_Input_Raw_Products'!F8<>"",'01_Input_Raw_Products'!F8,'01_Input_Raw_Products'!D8)&" "&'01_Input_Raw_Products'!I8) -> 0 | E8: =IF(C8="","",D8&" | GemPundit") -> 0 | F8: {=IF('01_Input_Raw_Products'!X8<>"",'01_Input_Raw_Products'!X8,IFERROR(_xlfn.XLOOKUP('01_Input_Raw_Products'!F8,'10_Master_Gem_Types'!A:A,'10_Master_Gem_Types'!O:O),LOWER(SUBSTITUTE(IF('01_Input_Raw_Products'!F8<>"",'01_Input_Raw_Products'!F8,'01_Input_Raw_Products'!D8)," ","-"))))} -> 0 | G8: ='01_Input_Raw_Products'!C8 -> 0 | H8: {=IF('01_Input_Raw_Products'!H8<>"",'01_Input_Raw_Products'!H8,IFERROR(_xlfn.XLOOKUP('01_Input_Raw_Products'!F8,'10_Master_Gem_Types'!A:A,'10_Master_Gem_Types'!D:D),""))} -> 0 | I8: =IF('01_Input_Raw_Products'!N8<>"",'01_Input_Raw_Products'!N8,IF('01_Input_Raw_Products'!O8<>"",'01_Input_Raw_Products'!O8*0.91,"")) -> 0 | J8: {=IFERROR(_xlfn.XLOOKUP('01_Input_Raw_Products'!F8,'10_Master_Gem_Types'!A:A,'10_Master_Gem_Types'!N:N),"")} -> 0 | K8: {=IF('01_Input_Raw_Products'!J8<>"",'01_Input_Raw_Products'!J8,IFERROR(_xlfn.XLOOKUP('01_Input_Raw_Products'!F8,'10_Master_Gem_Types'!A:A,'10_Master_Gem_Types'!E:E),""))} -> 0 | L8: ='01_Input_Raw_Products'!P8 -> 0 | M8: {=IFERROR(_xlfn.XLOOKUP('01_Input_Raw_Products'!K8,'12_Color_Mapping'!A:A,'12_Color_Mapping'!B:B),IFERROR(_xlfn.XLOOKUP('01_Input_Raw_Products'!F8,'10_Master_Gem_Types'!A:A,'10_Master_Gem_Types'!F:F),""))} -> 0 | N8: =IF(C8="","",IF('01_Input_Raw_Products'!F8<>"",'01_Input_Raw_Products'!F8,'01_Input_Raw_Products'!D8)) -> 0 | O8: =IF(C8="","","Catalog Automation") -> 0 | P8: ='01_Input_Raw_Products'!U8 -> 0 | Q8: =IF('01_Input_Raw_Products'!O8<>"",'01_Input_Raw_Products'!O8,IF('01_Input_Raw_Products'!N8<>"",'01_Input_Raw_Products'!N8*1.1,"")) -> 0 | R8: ='01_Input_Raw_Products'!S8 -> 0 | S8: {=IFERROR(_xlfn.XLOOKUP('01_Input_Raw_Products'!F8,'10_Master_Gem_Types'!A:A,'10_Master_Gem_Types'!H:H),"")} -> 0 | T8: ='01_Input_Raw_Products'!Q8 -> 0 | U8: ='01_Input_Raw_Products'!R8 -> 0 | V8: =I8 -> 0 | W8: {=IF('01_Input_Raw_Products'!G8<>"",'01_Input_Raw_Products'!G8,IFERROR(_xlfn.XLOOKUP('01_Input_Raw_Products'!F8,'10_Master_Gem_Types'!A:A,'10_Master_Gem_Types'!L:L),""))} -> 0 | X8: {=IFERROR(_xlfn.XLOOKUP('01_Input_Raw_Products'!F8,'10_Master_Gem_Types'!A:A,'10_Master_Gem_Types'!J:J),"")} -> 0 | Y8: {=IFERROR(_xlfn.XLOOKUP('01_Input_Raw_Products'!F8,'10_Master_Gem_Types'!A:A,'10_Master_Gem_Types'!I:I),"")} -> 0 | Z8: {=IFERROR(_xlfn.XLOOKUP('01_Input_Raw_Products'!L8,'13_Certification_Stickers'!A:A,'13_Certification_Stickers'!C:C),"")} -> 0 | AA8: {=IFERROR(_xlfn.XLOOKUP('01_Input_Raw_Products'!S8,'14_Shipping_Rules'!A:A,'14_Shipping_Rules'!B:B),"")} -> 0 | AB8: {=IFERROR(_xlfn.XLOOKUP('01_Input_Raw_Products'!D8,'16_Astro_Flags'!A:A,'16_Astro_Flags'!B:B),"")} -> 0 | AC8: =IF(C8="","","Catalog, Search") -> 0 | AD8: =IF(C8="","",IF(OR(F8="",J8="",M8="",S8="",Y8=""),"Manual Review","Ready")) -> 0 | AE8: =IF(C8="","",TEXTJOIN("; ",TRUE,IF(F8="","Missing url_key",""),IF(J8="","Missing classification",""),IF(M8="","Missing j_colour",""),IF(S8="","Missing hsn_code",""),IF(Y8="","Missing tax_class_id",""))) -> 0
A9: =IF('01_Input_Raw_Products'!B9<>"",20,"") -> 0 | B9: {=IF('01_Input_Raw_Products'!M9<>"",'01_Input_Raw_Products'!M9,IFERROR(_xlfn.XLOOKUP('01_Input_Raw_Products'!F9,'10_Master_Gem_Types'!A:A,'10_Master_Gem_Types'!K:K),""))} -> 0 | C9: ='01_Input_Raw_Products'!B9 -> 0 | D9: =IF(C9="","",TEXT(I9,"0.00")&" Ct "&IF('01_Input_Raw_Products'!F9<>"",'01_Input_Raw_Products'!F9,'01_Input_Raw_Products'!D9)&" "&'01_Input_Raw_Products'!I9) -> 0 | E9: =IF(C9="","",D9&" | GemPundit") -> 0 | F9: {=IF('01_Input_Raw_Products'!X9<>"",'01_Input_Raw_Products'!X9,IFERROR(_xlfn.XLOOKUP('01_Input_Raw_Products'!F9,'10_Master_Gem_Types'!A:A,'10_Master_Gem_Types'!O:O),LOWER(SUBSTITUTE(IF('01_Input_Raw_Products'!F9<>"",'01_Input_Raw_Products'!F9,'01_Input_Raw_Products'!D9)," ","-"))))} -> 0 | G9: ='01_Input_Raw_Products'!C9 -> 0 | H9: {=IF('01_Input_Raw_Products'!H9<>"",'01_Input_Raw_Products'!H9,IFERROR(_xlfn.XLOOKUP('01_Input_Raw_Products'!F9,'10_Master_Gem_Types'!A:A,'10_Master_Gem_Types'!D:D),""))} -> 0 | I9: =IF('01_Input_Raw_Products'!N9<>"",'01_Input_Raw_Products'!N9,IF('01_Input_Raw_Products'!O9<>"",'01_Input_Raw_Products'!O9*0.91,"")) -> 0 | J9: {=IFERROR(_xlfn.XLOOKUP('01_Input_Raw_Products'!F9,'10_Master_Gem_Types'!A:A,'10_Master_Gem_Types'!N:N),"")} -> 0 | K9: {=IF('01_Input_Raw_Products'!J9<>"",'01_Input_Raw_Products'!J9,IFERROR(_xlfn.XLOOKUP('01_Input_Raw_Products'!F9,'10_Master_Gem_Types'!A:A,'10_Master_Gem_Types'!E:E),""))} -> 0 | L9: ='01_Input_Raw_Products'!P9 -> 0 | M9: {=IFERROR(_xlfn.XLOOKUP('01_Input_Raw_Products'!K9,'12_Color_Mapping'!A:A,'12_Color_Mapping'!B:B),IFERROR(_xlfn.XLOOKUP('01_Input_Raw_Products'!F9,'10_Master_Gem_Types'!A:A,'10_Master_Gem_Types'!F:F),""))} -> 0 | N9: =IF(C9="","",IF('01_Input_Raw_Products'!F9<>"",'01_Input_Raw_Products'!F9,'01_Input_Raw_Products'!D9)) -> 0 | O9: =IF(C9="","","Catalog Automation") -> 0 | P9: ='01_Input_Raw_Products'!U9 -> 0 | Q9: =IF('01_Input_Raw_Products'!O9<>"",'01_Input_Raw_Products'!O9,IF('01_Input_Raw_Products'!N9<>"",'01_Input_Raw_Products'!N9*1.1,"")) -> 0 | R9: ='01_Input_Raw_Products'!S9 -> 0 | S9: {=IFERROR(_xlfn.XLOOKUP('01_Input_Raw_Products'!F9,'10_Master_Gem_Types'!A:A,'10_Master_Gem_Types'!H:H),"")} -> 0 | T9: ='01_Input_Raw_Products'!Q9 -> 0 | U9: ='01_Input_Raw_Products'!R9 -> 0 | V9: =I9 -> 0 | W9: {=IF('01_Input_Raw_Products'!G9<>"",'01_Input_Raw_Products'!G9,IFERROR(_xlfn.XLOOKUP('01_Input_Raw_Products'!F9,'10_Master_Gem_Types'!A:A,'10_Master_Gem_Types'!L:L),""))} -> 0 | X9: {=IFERROR(_xlfn.XLOOKUP('01_Input_Raw_Products'!F9,'10_Master_Gem_Types'!A:A,'10_Master_Gem_Types'!J:J),"")} -> 0 | Y9: {=IFERROR(_xlfn.XLOOKUP('01_Input_Raw_Products'!F9,'10_Master_Gem_Types'!A:A,'10_Master_Gem_Types'!I:I),"")} -> 0 | Z9: {=IFERROR(_xlfn.XLOOKUP('01_Input_Raw_Products'!L9,'13_Certification_Stickers'!A:A,'13_Certification_Stickers'!C:C),"")} -> 0 | AA9: {=IFERROR(_xlfn.XLOOKUP('01_Input_Raw_Products'!S9,'14_Shipping_Rules'!A:A,'14_Shipping_Rules'!B:B),"")} -> 0 | AB9: {=IFERROR(_xlfn.XLOOKUP('01_Input_Raw_Products'!D9,'16_Astro_Flags'!A:A,'16_Astro_Flags'!B:B),"")} -> 0 | AC9: =IF(C9="","","Catalog, Search") -> 0 | AD9: =IF(C9="","",IF(OR(F9="",J9="",M9="",S9="",Y9=""),"Manual Review","Ready")) -> 0 | AE9: =IF(C9="","",TEXTJOIN("; ",TRUE,IF(F9="","Missing url_key",""),IF(J9="","Missing classification",""),IF(M9="","Missing j_colour",""),IF(S9="","Missing hsn_code",""),IF(Y9="","Missing tax_class_id",""))) -> 0
A10: =IF('01_Input_Raw_Products'!B10<>"",20,"") -> 0 | B10: {=IF('01_Input_Raw_Products'!M10<>"",'01_Input_Raw_Products'!M10,IFERROR(_xlfn.XLOOKUP('01_Input_Raw_Products'!F10,'10_Master_Gem_Types'!A:A,'10_Master_Gem_Types'!K:K),""))} -> 0 | C10: ='01_Input_Raw_Products'!B10 -> 0 | D10: =IF(C10="","",TEXT(I10,"0.00")&" Ct "&IF('01_Input_Raw_Products'!F10<>"",'01_Input_Raw_Products'!F10,'01_Input_Raw_Products'!D10)&" "&'01_Input_Raw_Products'!I10) -> 0 | E10: =IF(C10="","",D10&" | GemPundit") -> 0 | F10: {=IF('01_Input_Raw_Products'!X10<>"",'01_Input_Raw_Products'!X10,IFERROR(_xlfn.XLOOKUP('01_Input_Raw_Products'!F10,'10_Master_Gem_Types'!A:A,'10_Master_Gem_Types'!O:O),LOWER(SUBSTITUTE(IF('01_Input_Raw_Products'!F10<>"",'01_Input_Raw_Products'!F10,'01_Input_Raw_Products'!D10)," ","-"))))} -> 0 | G10: ='01_Input_Raw_Products'!C10 -> 0 | H10: {=IF('01_Input_Raw_Products'!H10<>"",'01_Input_Raw_Products'!H10,IFERROR(_xlfn.XLOOKUP('01_Input_Raw_Products'!F10,'10_Master_Gem_Types'!A:A,'10_Master_Gem_Types'!D:D),""))} -> 0 | I10: =IF('01_Input_Raw_Products'!N10<>"",'01_Input_Raw_Products'!N10,IF('01_Input_Raw_Products'!O10<>"",'01_Input_Raw_Products'!O10*0.91,"")) -> 0 | J10: {=IFERROR(_xlfn.XLOOKUP('01_Input_Raw_Products'!F10,'10_Master_Gem_Types'!A:A,'10_Master_Gem_Types'!N:N),"")} -> 0 | K10: {=IF('01_Input_Raw_Products'!J10<>"",'01_Input_Raw_Products'!J10,IFERROR(_xlfn.XLOOKUP('01_Input_Raw_Products'!F10,'10_Master_Gem_Types'!A:A,'10_Master_Gem_Types'!E:E),""))} -> 0 | L10: ='01_Input_Raw_Products'!P10 -> 0 | M10: {=IFERROR(_xlfn.XLOOKUP('01_Input_Raw_Products'!K10,'12_Color_Mapping'!A:A,'12_Color_Mapping'!B:B),IFERROR(_xlfn.XLOOKUP('01_Input_Raw_Products'!F10,'10_Master_Gem_Types'!A:A,'10_Master_Gem_Types'!F:F),""))} -> 0 | N10: =IF(C10="","",IF('01_Input_Raw_Products'!F10<>"",'01_Input_Raw_Products'!F10,'01_Input_Raw_Products'!D10)) -> 0 | O10: =IF(C10="","","Catalog Automation") -> 0 | P10: ='01_Input_Raw_Products'!U10 -> 0 | Q10: =IF('01_Input_Raw_Products'!O10<>"",'01_Input_Raw_Products'!O10,IF('01_Input_Raw_Products'!N10<>"",'01_Input_Raw_Products'!N10*1.1,"")) -> 0 | R10: ='01_Input_Raw_Products'!S10 -> 0 | S10: {=IFERROR(_xlfn.XLOOKUP('01_Input_Raw_Products'!F10,'10_Master_Gem_Types'!A:A,'10_Master_Gem_Types'!H:H),"")} -> 0 | T10: ='01_Input_Raw_Products'!Q10 -> 0 | U10: ='01_Input_Raw_Products'!R10 -> 0 | V10: =I10 -> 0 | W10: {=IF('01_Input_Raw_Products'!G10<>"",'01_Input_Raw_Products'!G10,IFERROR(_xlfn.XLOOKUP('01_Input_Raw_Products'!F10,'10_Master_Gem_Types'!A:A,'10_Master_Gem_Types'!L:L),""))} -> 0 | X10: {=IFERROR(_xlfn.XLOOKUP('01_Input_Raw_Products'!F10,'10_Master_Gem_Types'!A:A,'10_Master_Gem_Types'!J:J),"")} -> 0 | Y10: {=IFERROR(_xlfn.XLOOKUP('01_Input_Raw_Products'!F10,'10_Master_Gem_Types'!A:A,'10_Master_Gem_Types'!I:I),"")} -> 0 | Z10: {=IFERROR(_xlfn.XLOOKUP('01_Input_Raw_Products'!L10,'13_Certification_Stickers'!A:A,'13_Certification_Stickers'!C:C),"")} -> 0 | AA10: {=IFERROR(_xlfn.XLOOKUP('01_Input_Raw_Products'!S10,'14_Shipping_Rules'!A:A,'14_Shipping_Rules'!B:B),"")} -> 0 | AB10: {=IFERROR(_xlfn.XLOOKUP('01_Input_Raw_Products'!D10,'16_Astro_Flags'!A:A,'16_Astro_Flags'!B:B),"")} -> 0 | AC10: =IF(C10="","","Catalog, Search") -> 0 | AD10: =IF(C10="","",IF(OR(F10="",J10="",M10="",S10="",Y10=""),"Manual Review","Ready")) -> 0 | AE10: =IF(C10="","",TEXTJOIN("; ",TRUE,IF(F10="","Missing url_key",""),IF(J10="","Missing classification",""),IF(M10="","Missing j_colour",""),IF(S10="","Missing hsn_code",""),IF(Y10="","Missing tax_class_id",""))) -> 0
A11: =IF('01_Input_Raw_Products'!B11<>"",20,"") -> 0 | B11: {=IF('01_Input_Raw_Products'!M11<>"",'01_Input_Raw_Products'!M11,IFERROR(_xlfn.XLOOKUP('01_Input_Raw_Products'!F11,'10_Master_Gem_Types'!A:A,'10_Master_Gem_Types'!K:K),""))} -> 0 | C11: ='01_Input_Raw_Products'!B11 -> 0 | D11: =IF(C11="","",TEXT(I11,"0.00")&" Ct "&IF('01_Input_Raw_Products'!F11<>"",'01_Input_Raw_Products'!F11,'01_Input_Raw_Products'!D11)&" "&'01_Input_Raw_Products'!I11) -> 0 | E11: =IF(C11="","",D11&" | GemPundit") -> 0 | F11: {=IF('01_Input_Raw_Products'!X11<>"",'01_Input_Raw_Products'!X11,IFERROR(_xlfn.XLOOKUP('01_Input_Raw_Products'!F11,'10_Master_Gem_Types'!A:A,'10_Master_Gem_Types'!O:O),LOWER(SUBSTITUTE(IF('01_Input_Raw_Products'!F11<>"",'01_Input_Raw_Products'!F11,'01_Input_Raw_Products'!D11)," ","-"))))} -> 0 | G11: ='01_Input_Raw_Products'!C11 -> 0 | H11: {=IF('01_Input_Raw_Products'!H11<>"",'01_Input_Raw_Products'!H11,IFERROR(_xlfn.XLOOKUP('01_Input_Raw_Products'!F11,'10_Master_Gem_Types'!A:A,'10_Master_Gem_Types'!D:D),""))} -> 0 | I11: =IF('01_Input_Raw_Products'!N11<>"",'01_Input_Raw_Products'!N11,IF('01_Input_Raw_Products'!O11<>"",'01_Input_Raw_Products'!O11*0.91,"")) -> 0 | J11: {=IFERROR(_xlfn.XLOOKUP('01_Input_Raw_Products'!F11,'10_Master_Gem_Types'!A:A,'10_Master_Gem_Types'!N:N),"")} -> 0 | K11: {=IF('01_Input_Raw_Products'!J11<>"",'01_Input_Raw_Products'!J11,IFERROR(_xlfn.XLOOKUP('01_Input_Raw_Products'!F11,'10_Master_Gem_Types'!A:A,'10_Master_Gem_Types'!E:E),""))} -> 0 | L11: ='01_Input_Raw_Products'!P11 -> 0 | M11: {=IFERROR(_xlfn.XLOOKUP('01_Input_Raw_Products'!K11,'12_Color_Mapping'!A:A,'12_Color_Mapping'!B:B),IFERROR(_xlfn.XLOOKUP('01_Input_Raw_Products'!F11,'10_Master_Gem_Types'!A:A,'10_Master_Gem_Types'!F:F),""))} -> 0 | N11: =IF(C11="","",IF('01_Input_Raw_Products'!F11<>"",'01_Input_Raw_Products'!F11,'01_Input_Raw_Products'!D11)) -> 0 | O11: =IF(C11="","","Catalog Automation") -> 0 | P11: ='01_Input_Raw_Products'!U11 -> 0 | Q11: =IF('01_Input_Raw_Products'!O11<>"",'01_Input_Raw_Products'!O11,IF('01_Input_Raw_Products'!N11<>"",'01_Input_Raw_Products'!N11*1.1,"")) -> 0 | R11: ='01_Input_Raw_Products'!S11 -> 0 | S11: {=IFERROR(_xlfn.XLOOKUP('01_Input_Raw_Products'!F11,'10_Master_Gem_Types'!A:A,'10_Master_Gem_Types'!H:H),"")} -> 0 | T11: ='01_Input_Raw_Products'!Q11 -> 0 | U11: ='01_Input_Raw_Products'!R11 -> 0 | V11: =I11 -> 0 | W11: {=IF('01_Input_Raw_Products'!G11<>"",'01_Input_Raw_Products'!G11,IFERROR(_xlfn.XLOOKUP('01_Input_Raw_Products'!F11,'10_Master_Gem_Types'!A:A,'10_Master_Gem_Types'!L:L),""))} -> 0 | X11: {=IFERROR(_xlfn.XLOOKUP('01_Input_Raw_Products'!F11,'10_Master_Gem_Types'!A:A,'10_Master_Gem_Types'!J:J),"")} -> 0 | Y11: {=IFERROR(_xlfn.XLOOKUP('01_Input_Raw_Products'!F11,'10_Master_Gem_Types'!A:A,'10_Master_Gem_Types'!I:I),"")} -> 0 | Z11: {=IFERROR(_xlfn.XLOOKUP('01_Input_Raw_Products'!L11,'13_Certification_Stickers'!A:A,'13_Certification_Stickers'!C:C),"")} -> 0 | AA11: {=IFERROR(_xlfn.XLOOKUP('01_Input_Raw_Products'!S11,'14_Shipping_Rules'!A:A,'14_Shipping_Rules'!B:B),"")} -> 0 | AB11: {=IFERROR(_xlfn.XLOOKUP('01_Input_Raw_Products'!D11,'16_Astro_Flags'!A:A,'16_Astro_Flags'!B:B),"")} -> 0 | AC11: =IF(C11="","","Catalog, Search") -> 0 | AD11: =IF(C11="","",IF(OR(F11="",J11="",M11="",S11="",Y11=""),"Manual Review","Ready")) -> 0 | AE11: =IF(C11="","",TEXTJOIN("; ",TRUE,IF(F11="","Missing url_key",""),IF(J11="","Missing classification",""),IF(M11="","Missing j_colour",""),IF(S11="","Missing hsn_code",""),IF(Y11="","Missing tax_class_id",""))) -> 0
A12: =IF('01_Input_Raw_Products'!B12<>"",20,"") -> 0 | B12: {=IF('01_Input_Raw_Products'!M12<>"",'01_Input_Raw_Products'!M12,IFERROR(_xlfn.XLOOKUP('01_Input_Raw_Products'!F12,'10_Master_Gem_Types'!A:A,'10_Master_Gem_Types'!K:K),""))} -> 0 | C12: ='01_Input_Raw_Products'!B12 -> 0 | D12: =IF(C12="","",TEXT(I12,"0.00")&" Ct "&IF('01_Input_Raw_Products'!F12<>"",'01_Input_Raw_Products'!F12,'01_Input_Raw_Products'!D12)&" "&'01_Input_Raw_Products'!I12) -> 0 | E12: =IF(C12="","",D12&" | GemPundit") -> 0 | F12: {=IF('01_Input_Raw_Products'!X12<>"",'01_Input_Raw_Products'!X12,IFERROR(_xlfn.XLOOKUP('01_Input_Raw_Products'!F12,'10_Master_Gem_Types'!A:A,'10_Master_Gem_Types'!O:O),LOWER(SUBSTITUTE(IF('01_Input_Raw_Products'!F12<>"",'01_Input_Raw_Products'!F12,'01_Input_Raw_Products'!D12)," ","-"))))} -> 0 | G12: ='01_Input_Raw_Products'!C12 -> 0 | H12: {=IF('01_Input_Raw_Products'!H12<>"",'01_Input_Raw_Products'!H12,IFERROR(_xlfn.XLOOKUP('01_Input_Raw_Products'!F12,'10_Master_Gem_Types'!A:A,'10_Master_Gem_Types'!D:D),""))} -> 0 | I12: =IF('01_Input_Raw_Products'!N12<>"",'01_Input_Raw_Products'!N12,IF('01_Input_Raw_Products'!O12<>"",'01_Input_Raw_Products'!O12*0.91,"")) -> 0 | J12: {=IFERROR(_xlfn.XLOOKUP('01_Input_Raw_Products'!F12,'10_Master_Gem_Types'!A:A,'10_Master_Gem_Types'!N:N),"")} -> 0 | K12: {=IF('01_Input_Raw_Products'!J12<>"",'01_Input_Raw_Products'!J12,IFERROR(_xlfn.XLOOKUP('01_Input_Raw_Products'!F12,'10_Master_Gem_Types'!A:A,'10_Master_Gem_Types'!E:E),""))} -> 0 | L12: ='01_Input_Raw_Products'!P12 -> 0 | M12: {=IFERROR(_xlfn.XLOOKUP('01_Input_Raw_Products'!K12,'12_Color_Mapping'!A:A,'12_Color_Mapping'!B:B),IFERROR(_xlfn.XLOOKUP('01_Input_Raw_Products'!F12,'10_Master_Gem_Types'!A:A,'10_Master_Gem_Types'!F:F),""))} -> 0 | N12: =IF(C12="","",IF('01_Input_Raw_Products'!F12<>"",'01_Input_Raw_Products'!F12,'01_Input_Raw_Products'!D12)) -> 0 | O12: =IF(C12="","","Catalog Automation") -> 0 | P12: ='01_Input_Raw_Products'!U12 -> 0 | Q12: =IF('01_Input_Raw_Products'!O12<>"",'01_Input_Raw_Products'!O12,IF('01_Input_Raw_Products'!N12<>"",'01_Input_Raw_Products'!N12*1.1,"")) -> 0 | R12: ='01_Input_Raw_Products'!S12 -> 0 | S12: {=IFERROR(_xlfn.XLOOKUP('01_Input_Raw_Products'!F12,'10_Master_Gem_Types'!A:A,'10_Master_Gem_Types'!H:H),"")} -> 0 | T12: ='01_Input_Raw_Products'!Q12 -> 0 | U12: ='01_Input_Raw_Products'!R12 -> 0 | V12: =I12 -> 0 | W12: {=IF('01_Input_Raw_Products'!G12<>"",'01_Input_Raw_Products'!G12,IFERROR(_xlfn.XLOOKUP('01_Input_Raw_Products'!F12,'10_Master_Gem_Types'!A:A,'10_Master_Gem_Types'!L:L),""))} -> 0 | X12: {=IFERROR(_xlfn.XLOOKUP('01_Input_Raw_Products'!F12,'10_Master_Gem_Types'!A:A,'10_Master_Gem_Types'!J:J),"")} -> 0 | Y12: {=IFERROR(_xlfn.XLOOKUP('01_Input_Raw_Products'!F12,'10_Master_Gem_Types'!A:A,'10_Master_Gem_Types'!I:I),"")} -> 0 | Z12: {=IFERROR(_xlfn.XLOOKUP('01_Input_Raw_Products'!L12,'13_Certification_Stickers'!A:A,'13_Certification_Stickers'!C:C),"")} -> 0 | AA12: {=IFERROR(_xlfn.XLOOKUP('01_Input_Raw_Products'!S12,'14_Shipping_Rules'!A:A,'14_Shipping_Rules'!B:B),"")} -> 0 | AB12: {=IFERROR(_xlfn.XLOOKUP('01_Input_Raw_Products'!D12,'16_Astro_Flags'!A:A,'16_Astro_Flags'!B:B),"")} -> 0 | AC12: =IF(C12="","","Catalog, Search") -> 0 | AD12: =IF(C12="","",IF(OR(F12="",J12="",M12="",S12="",Y12=""),"Manual Review","Ready")) -> 0 | AE12: =IF(C12="","",TEXTJOIN("; ",TRUE,IF(F12="","Missing url_key",""),IF(J12="","Missing classification",""),IF(M12="","Missing j_colour",""),IF(S12="","Missing hsn_code",""),IF(Y12="","Missing tax_class_id",""))) -> 0
A13: =IF('01_Input_Raw_Products'!B13<>"",20,"") -> 0 | B13: {=IF('01_Input_Raw_Products'!M13<>"",'01_Input_Raw_Products'!M13,IFERROR(_xlfn.XLOOKUP('01_Input_Raw_Products'!F13,'10_Master_Gem_Types'!A:A,'10_Master_Gem_Types'!K:K),""))} -> 0 | C13: ='01_Input_Raw_Products'!B13 -> 0 | D13: =IF(C13="","",TEXT(I13,"0.00")&" Ct "&IF('01_Input_Raw_Products'!F13<>"",'01_Input_Raw_Products'!F13,'01_Input_Raw_Products'!D13)&" "&'01_Input_Raw_Products'!I13) -> 0 | E13: =IF(C13="","",D13&" | GemPundit") -> 0 | F13: {=IF('01_Input_Raw_Products'!X13<>"",'01_Input_Raw_Products'!X13,IFERROR(_xlfn.XLOOKUP('01_Input_Raw_Products'!F13,'10_Master_Gem_Types'!A:A,'10_Master_Gem_Types'!O:O),LOWER(SUBSTITUTE(IF('01_Input_Raw_Products'!F13<>"",'01_Input_Raw_Products'!F13,'01_Input_Raw_Products'!D13)," ","-"))))} -> 0 | G13: ='01_Input_Raw_Products'!C13 -> 0 | H13: {=IF('01_Input_Raw_Products'!H13<>"",'01_Input_Raw_Products'!H13,IFERROR(_xlfn.XLOOKUP('01_Input_Raw_Products'!F13,'10_Master_Gem_Types'!A:A,'10_Master_Gem_Types'!D:D),""))} -> 0 | I13: =IF('01_Input_Raw_Products'!N13<>"",'01_Input_Raw_Products'!N13,IF('01_Input_Raw_Products'!O13<>"",'01_Input_Raw_Products'!O13*0.91,"")) -> 0 | J13: {=IFERROR(_xlfn.XLOOKUP('01_Input_Raw_Products'!F13,'10_Master_Gem_Types'!A:A,'10_Master_Gem_Types'!N:N),"")} -> 0 | K13: {=IF('01_Input_Raw_Products'!J13<>"",'01_Input_Raw_Products'!J13,IFERROR(_xlfn.XLOOKUP('01_Input_Raw_Products'!F13,'10_Master_Gem_Types'!A:A,'10_Master_Gem_Types'!E:E),""))} -> 0 | L13: ='01_Input_Raw_Products'!P13 -> 0 | M13: {=IFERROR(_xlfn.XLOOKUP('01_Input_Raw_Products'!K13,'12_Color_Mapping'!A:A,'12_Color_Mapping'!B:B),IFERROR(_xlfn.XLOOKUP('01_Input_Raw_Products'!F13,'10_Master_Gem_Types'!A:A,'10_Master_Gem_Types'!F:F),""))} -> 0 | N13: =IF(C13="","",IF('01_Input_Raw_Products'!F13<>"",'01_Input_Raw_Products'!F13,'01_Input_Raw_Products'!D13)) -> 0 | O13: =IF(C13="","","Catalog Automation") -> 0 | P13: ='01_Input_Raw_Products'!U13 -> 0 | Q13: =IF('01_Input_Raw_Products'!O13<>"",'01_Input_Raw_Products'!O13,IF('01_Input_Raw_Products'!N13<>"",'01_Input_Raw_Products'!N13*1.1,"")) -> 0 | R13: ='01_Input_Raw_Products'!S13 -> 0 | S13: {=IFERROR(_xlfn.XLOOKUP('01_Input_Raw_Products'!F13,'10_Master_Gem_Types'!A:A,'10_Master_Gem_Types'!H:H),"")} -> 0 | T13: ='01_Input_Raw_Products'!Q13 -> 0 | U13: ='01_Input_Raw_Products'!R13 -> 0 | V13: =I13 -> 0 | W13: {=IF('01_Input_Raw_Products'!G13<>"",'01_Input_Raw_Products'!G13,IFERROR(_xlfn.XLOOKUP('01_Input_Raw_Products'!F13,'10_Master_Gem_Types'!A:A,'10_Master_Gem_Types'!L:L),""))} -> 0 | X13: {=IFERROR(_xlfn.XLOOKUP('01_Input_Raw_Products'!F13,'10_Master_Gem_Types'!A:A,'10_Master_Gem_Types'!J:J),"")} -> 0 | Y13: {=IFERROR(_xlfn.XLOOKUP('01_Input_Raw_Products'!F13,'10_Master_Gem_Types'!A:A,'10_Master_Gem_Types'!I:I),"")} -> 0 | Z13: {=IFERROR(_xlfn.XLOOKUP('01_Input_Raw_Products'!L13,'13_Certification_Stickers'!A:A,'13_Certification_Stickers'!C:C),"")} -> 0 | AA13: {=IFERROR(_xlfn.XLOOKUP('01_Input_Raw_Products'!S13,'14_Shipping_Rules'!A:A,'14_Shipping_Rules'!B:B),"")} -> 0 | AB13: {=IFERROR(_xlfn.XLOOKUP('01_Input_Raw_Products'!D13,'16_Astro_Flags'!A:A,'16_Astro_Flags'!B:B),"")} -> 0 | AC13: =IF(C13="","","Catalog, Search") -> 0 | AD13: =IF(C13="","",IF(OR(F13="",J13="",M13="",S13="",Y13=""),"Manual Review","Ready")) -> 0 | AE13: =IF(C13="","",TEXTJOIN("; ",TRUE,IF(F13="","Missing url_key",""),IF(J13="","Missing classification",""),IF(M13="","Missing j_colour",""),IF(S13="","Missing hsn_code",""),IF(Y13="","Missing tax_class_id",""))) -> 0
A14: =IF('01_Input_Raw_Products'!B14<>"",20,"") -> 0 | B14: {=IF('01_Input_Raw_Products'!M14<>"",'01_Input_Raw_Products'!M14,IFERROR(_xlfn.XLOOKUP('01_Input_Raw_Products'!F14,'10_Master_Gem_Types'!A:A,'10_Master_Gem_Types'!K:K),""))} -> 0 | C14: ='01_Input_Raw_Products'!B14 -> 0 | D14: =IF(C14="","",TEXT(I14,"0.00")&" Ct "&IF('01_Input_Raw_Products'!F14<>"",'01_Input_Raw_Products'!F14,'01_Input_Raw_Products'!D14)&" "&'01_Input_Raw_Products'!I14) -> 0 | E14: =IF(C14="","",D14&" | GemPundit") -> 0 | F14: {=IF('01_Input_Raw_Products'!X14<>"",'01_Input_Raw_Products'!X14,IFERROR(_xlfn.XLOOKUP('01_Input_Raw_Products'!F14,'10_Master_Gem_Types'!A:A,'10_Master_Gem_Types'!O:O),LOWER(SUBSTITUTE(IF('01_Input_Raw_Products'!F14<>"",'01_Input_Raw_Products'!F14,'01_Input_Raw_Products'!D14)," ","-"))))} -> 0 | G14: ='01_Input_Raw_Products'!C14 -> 0 | H14: {=IF('01_Input_Raw_Products'!H14<>"",'01_Input_Raw_Products'!H14,IFERROR(_xlfn.XLOOKUP('01_Input_Raw_Products'!F14,'10_Master_Gem_Types'!A:A,'10_Master_Gem_Types'!D:D),""))} -> 0 | I14: =IF('01_Input_Raw_Products'!N14<>"",'01_Input_Raw_Products'!N14,IF('01_Input_Raw_Products'!O14<>"",'01_Input_Raw_Products'!O14*0.91,"")) -> 0 | J14: {=IFERROR(_xlfn.XLOOKUP('01_Input_Raw_Products'!F14,'10_Master_Gem_Types'!A:A,'10_Master_Gem_Types'!N:N),"")} -> 0 | K14: {=IF('01_Input_Raw_Products'!J14<>"",'01_Input_Raw_Products'!J14,IFERROR(_xlfn.XLOOKUP('01_Input_Raw_Products'!F14,'10_Master_Gem_Types'!A:A,'10_Master_Gem_Types'!E:E),""))} -> 0 | L14: ='01_Input_Raw_Products'!P14 -> 0 | M14: {=IFERROR(_xlfn.XLOOKUP('01_Input_Raw_Products'!K14,'12_Color_Mapping'!A:A,'12_Color_Mapping'!B:B),IFERROR(_xlfn.XLOOKUP('01_Input_Raw_Products'!F14,'10_Master_Gem_Types'!A:A,'10_Master_Gem_Types'!F:F),""))} -> 0 | N14: =IF(C14="","",IF('01_Input_Raw_Products'!F14<>"",'01_Input_Raw_Products'!F14,'01_Input_Raw_Products'!D14)) -> 0 | O14: =IF(C14="","","Catalog Automation") -> 0 | P14: ='01_Input_Raw_Products'!U14 -> 0 | Q14: =IF('01_Input_Raw_Products'!O14<>"",'01_Input_Raw_Products'!O14,IF('01_Input_Raw_Products'!N14<>"",'01_Input_Raw_Products'!N14*1.1,"")) -> 0 | R14: ='01_Input_Raw_Products'!S14 -> 0 | S14: {=IFERROR(_xlfn.XLOOKUP('01_Input_Raw_Products'!F14,'10_Master_Gem_Types'!A:A,'10_Master_Gem_Types'!H:H),"")} -> 0 | T14: ='01_Input_Raw_Products'!Q14 -> 0 | U14: ='01_Input_Raw_Products'!R14 -> 0 | V14: =I14 -> 0 | W14: {=IF('01_Input_Raw_Products'!G14<>"",'01_Input_Raw_Products'!G14,IFERROR(_xlfn.XLOOKUP('01_Input_Raw_Products'!F14,'10_Master_Gem_Types'!A:A,'10_Master_Gem_Types'!L:L),""))} -> 0 | X14: {=IFERROR(_xlfn.XLOOKUP('01_Input_Raw_Products'!F14,'10_Master_Gem_Types'!A:A,'10_Master_Gem_Types'!J:J),"")} -> 0 | Y14: {=IFERROR(_xlfn.XLOOKUP('01_Input_Raw_Products'!F14,'10_Master_Gem_Types'!A:A,'10_Master_Gem_Types'!I:I),"")} -> 0 | Z14: {=IFERROR(_xlfn.XLOOKUP('01_Input_Raw_Products'!L14,'13_Certification_Stickers'!A:A,'13_Certification_Stickers'!C:C),"")} -> 0 | AA14: {=IFERROR(_xlfn.XLOOKUP('01_Input_Raw_Products'!S14,'14_Shipping_Rules'!A:A,'14_Shipping_Rules'!B:B),"")} -> 0 | AB14: {=IFERROR(_xlfn.XLOOKUP('01_Input_Raw_Products'!D14,'16_Astro_Flags'!A:A,'16_Astro_Flags'!B:B),"")} -> 0 | AC14: =IF(C14="","","Catalog, Search") -> 0 | AD14: =IF(C14="","",IF(OR(F14="",J14="",M14="",S14="",Y14=""),"Manual Review","Ready")) -> 0 | AE14: =IF(C14="","",TEXTJOIN("; ",TRUE,IF(F14="","Missing url_key",""),IF(J14="","Missing classification",""),IF(M14="","Missing j_colour",""),IF(S14="","Missing hsn_code",""),IF(Y14="","Missing tax_class_id",""))) -> 0
A15: =IF('01_Input_Raw_Products'!B15<>"",20,"") -> 0 | B15: {=IF('01_Input_Raw_Products'!M15<>"",'01_Input_Raw_Products'!M15,IFERROR(_xlfn.XLOOKUP('01_Input_Raw_Products'!F15,'10_Master_Gem_Types'!A:A,'10_Master_Gem_Types'!K:K),""))} -> 0 | C15: ='01_Input_Raw_Products'!B15 -> 0 | D15: =IF(C15="","",TEXT(I15,"0.00")&" Ct "&IF('01_Input_Raw_Products'!F15<>"",'01_Input_Raw_Products'!F15,'01_Input_Raw_Products'!D15)&" "&'01_Input_Raw_Products'!I15) -> 0 | E15: =IF(C15="","",D15&" | GemPundit") -> 0 | F15: {=IF('01_Input_Raw_Products'!X15<>"",'01_Input_Raw_Products'!X15,IFERROR(_xlfn.XLOOKUP('01_Input_Raw_Products'!F15,'10_Master_Gem_Types'!A:A,'10_Master_Gem_Types'!O:O),LOWER(SUBSTITUTE(IF('01_Input_Raw_Products'!F15<>"",'01_Input_Raw_Products'!F15,'01_Input_Raw_Products'!D15)," ","-"))))} -> 0 | G15: ='01_Input_Raw_Products'!C15 -> 0 | H15: {=IF('01_Input_Raw_Products'!H15<>"",'01_Input_Raw_Products'!H15,IFERROR(_xlfn.XLOOKUP('01_Input_Raw_Products'!F15,'10_Master_Gem_Types'!A:A,'10_Master_Gem_Types'!D:D),""))} -> 0 | I15: =IF('01_Input_Raw_Products'!N15<>"",'01_Input_Raw_Products'!N15,IF('01_Input_Raw_Products'!O15<>"",'01_Input_Raw_Products'!O15*0.91,"")) -> 0 | J15: {=IFERROR(_xlfn.XLOOKUP('01_Input_Raw_Products'!F15,'10_Master_Gem_Types'!A:A,'10_Master_Gem_Types'!N:N),"")} -> 0 | K15: {=IF('01_Input_Raw_Products'!J15<>"",'01_Input_Raw_Products'!J15,IFERROR(_xlfn.XLOOKUP('01_Input_Raw_Products'!F15,'10_Master_Gem_Types'!A:A,'10_Master_Gem_Types'!E:E),""))} -> 0 | L15: ='01_Input_Raw_Products'!P15 -> 0 | M15: {=IFERROR(_xlfn.XLOOKUP('01_Input_Raw_Products'!K15,'12_Color_Mapping'!A:A,'12_Color_Mapping'!B:B),IFERROR(_xlfn.XLOOKUP('01_Input_Raw_Products'!F15,'10_Master_Gem_Types'!A:A,'10_Master_Gem_Types'!F:F),""))} -> 0 | N15: =IF(C15="","",IF('01_Input_Raw_Products'!F15<>"",'01_Input_Raw_Products'!F15,'01_Input_Raw_Products'!D15)) -> 0 | O15: =IF(C15="","","Catalog Automation") -> 0 | P15: ='01_Input_Raw_Products'!U15 -> 0 | Q15: =IF('01_Input_Raw_Products'!O15<>"",'01_Input_Raw_Products'!O15,IF('01_Input_Raw_Products'!N15<>"",'01_Input_Raw_Products'!N15*1.1,"")) -> 0 | R15: ='01_Input_Raw_Products'!S15 -> 0 | S15: {=IFERROR(_xlfn.XLOOKUP('01_Input_Raw_Products'!F15,'10_Master_Gem_Types'!A:A,'10_Master_Gem_Types'!H:H),"")} -> 0 | T15: ='01_Input_Raw_Products'!Q15 -> 0 | U15: ='01_Input_Raw_Products'!R15 -> 0 | V15: =I15 -> 0 | W15: {=IF('01_Input_Raw_Products'!G15<>"",'01_Input_Raw_Products'!G15,IFERROR(_xlfn.XLOOKUP('01_Input_Raw_Products'!F15,'10_Master_Gem_Types'!A:A,'10_Master_Gem_Types'!L:L),""))} -> 0 | X15: {=IFERROR(_xlfn.XLOOKUP('01_Input_Raw_Products'!F15,'10_Master_Gem_Types'!A:A,'10_Master_Gem_Types'!J:J),"")} -> 0 | Y15: {=IFERROR(_xlfn.XLOOKUP('01_Input_Raw_Products'!F15,'10_Master_Gem_Types'!A:A,'10_Master_Gem_Types'!I:I),"")} -> 0 | Z15: {=IFERROR(_xlfn.XLOOKUP('01_Input_Raw_Products'!L15,'13_Certification_Stickers'!A:A,'13_Certification_Stickers'!C:C),"")} -> 0 | AA15: {=IFERROR(_xlfn.XLOOKUP('01_Input_Raw_Products'!S15,'14_Shipping_Rules'!A:A,'14_Shipping_Rules'!B:B),"")} -> 0 | AB15: {=IFERROR(_xlfn.XLOOKUP('01_Input_Raw_Products'!D15,'16_Astro_Flags'!A:A,'16_Astro_Flags'!B:B),"")} -> 0 | AC15: =IF(C15="","","Catalog, Search") -> 0 | AD15: =IF(C15="","",IF(OR(F15="",J15="",M15="",S15="",Y15=""),"Manual Review","Ready")) -> 0 | AE15: =IF(C15="","",TEXTJOIN("; ",TRUE,IF(F15="","Missing url_key",""),IF(J15="","Missing classification",""),IF(M15="","Missing j_colour",""),IF(S15="","Missing hsn_code",""),IF(Y15="","Missing tax_class_id",""))) -> 0
... A503: =IF('01_Input_Raw_Products'!B503<>"",20,"") -> 0 | B503: {=IF('01_Input_Raw_Products'!M503<>"",'01_Input_Raw_Products'!M503,IFERROR(_xlfn.XLOOKUP('01_Input_Raw_Products'!F503,'10_Master_Gem_Types'!A:A,'10_Master_Gem_Types'!K:K),""))} -> 0 | C503: ='01_Input_Raw_Products'!B503 -> 0 | D503: =IF(C503="","",TEXT(I503,"0.00")&" Ct "&IF('01_Input_Raw_Products'!F503<>"",'01_Input_Raw_Products'!F503,'01_Input_Raw_Products'!D503)&" "&'01_Input_Raw_Products'!I503) -> 0 | E503: =IF(C503="","",D503&" | GemPundit") -> 0 | F503: {=IF('01_Input_Raw_Products'!X503<>"",'01_Input_Raw_Products'!X503,IFERROR(_xlfn.XLOOKUP('01_Input_Raw_Products'!F503,'10_Master_Gem_Types'!A:A,'10_Master_Gem_Types'!O:O),LOWER(SUBSTITUTE(IF('01_Input_Raw_Products'!F503<>"",'01_Input_Raw_Products'!F503,'01_Input_Raw_Products'!D503)," ","-"))))} -> 0 | G503: ='01_Input_Raw_Products'!C503 -> 0 | H503: {=IF('01_Input_Raw_Products'!H503<>"",'01_Input_Raw_Products'!H503,IFERROR(_xlfn.XLOOKUP('01_Input_Raw_Products'!F503,'10_Master_Gem_Types'!A:A,'10_Master_Gem_Types'!D:D),""))} -> 0 | I503: =IF('01_Input_Raw_Products'!N503<>"",'01_Input_Raw_Products'!N503,IF('01_Input_Raw_Products'!O503<>"",'01_Input_Raw_Products'!O503*0.91,"")) -> 0 | J503: {=IFERROR(_xlfn.XLOOKUP('01_Input_Raw_Products'!F503,'10_Master_Gem_Types'!A:A,'10_Master_Gem_Types'!N:N),"")} -> 0 | K503: {=IF('01_Input_Raw_Products'!J503<>"",'01_Input_Raw_Products'!J503,IFERROR(_xlfn.XLOOKUP('01_Input_Raw_Products'!F503,'10_Master_Gem_Types'!A:A,'10_Master_Gem_Types'!E:E),""))} -> 0 | L503: ='01_Input_Raw_Products'!P503 -> 0 | M503: {=IFERROR(_xlfn.XLOOKUP('01_Input_Raw_Products'!K503,'12_Color_Mapping'!A:A,'12_Color_Mapping'!B:B),IFERROR(_xlfn.XLOOKUP('01_Input_Raw_Products'!F503,'10_Master_Gem_Types'!A:A,'10_Master_Gem_Types'!F:F),""))} -> 0 | N503: =IF(C503="","",IF('01_Input_Raw_Products'!F503<>"",'01_Input_Raw_Products'!F503,'01_Input_Raw_Products'!D503)) -> 0 | O503: =IF(C503="","","Catalog Automation") -> 0 | P503: ='01_Input_Raw_Products'!U503 -> 0 | Q503: =IF('01_Input_Raw_Products'!O503<>"",'01_Input_Raw_Products'!O503,IF('01_Input_Raw_Products'!N503<>"",'01_Input_Raw_Products'!N503*1.1,"")) -> 0 | R503: ='01_Input_Raw_Products'!S503 -> 0 | S503: {=IFERROR(_xlfn.XLOOKUP('01_Input_Raw_Products'!F503,'10_Master_Gem_Types'!A:A,'10_Master_Gem_Types'!H:H),"")} -> 0 | T503: ='01_Input_Raw_Products'!Q503 -> 0 | U503: ='01_Input_Raw_Products'!R503 -> 0 | V503: =I503 -> 0 | W503: {=IF('01_Input_Raw_Products'!G503<>"",'01_Input_Raw_Products'!G503,IFERROR(_xlfn.XLOOKUP('01_Input_Raw_Products'!F503,'10_Master_Gem_Types'!A:A,'10_Master_Gem_Types'!L:L),""))} -> 0 | X503: {=IFERROR(_xlfn.XLOOKUP('01_Input_Raw_Products'!F503,'10_Master_Gem_Types'!A:A,'10_Master_Gem_Types'!J:J),"")} -> 0 | Y503: {=IFERROR(_xlfn.XLOOKUP('01_Input_Raw_Products'!F503,'10_Master_Gem_Types'!A:A,'10_Master_Gem_Types'!I:I),"")} -> 0 | Z503: {=IFERROR(_xlfn.XLOOKUP('01_Input_Raw_Products'!L503,'13_Certification_Stickers'!A:A,'13_Certification_Stickers'!C:C),"")} -> 0 | AA503: {=IFERROR(_xlfn.XLOOKUP('01_Input_Raw_Products'!S503,'14_Shipping_Rules'!A:A,'14_Shipping_Rules'!B:B),"")} -> 0 | AB503: {=IFERROR(_xlfn.XLOOKUP('01_Input_Raw_Products'!D503,'16_Astro_Flags'!A:A,'16_Astro_Flags'!B:B),"")} -> 0 | AC503: =IF(C503="","","Catalog, Search") -> 0 | AD503: =IF(C503="","",IF(OR(F503="",J503="",M503="",S503="",Y503=""),"Manual Review","Ready")) -> 0 | AE503: =IF(C503="","",TEXTJOIN("; ",TRUE,IF(F503="","Missing url_key",""),IF(J503="","Missing classification",""),IF(M503="","Missing j_colour",""),IF(S503="","Missing hsn_code",""),IF(Y503="","Missing tax_class_id",""))) -> 0

Sheet 03_Validation_Report
A1: 03_Validation_Report
A2: Use this sheet for manual-review queue and QA sign-off.
A3: row_id | B3: sku | C3: severity | D3: field | E3: issue | F3: recommended_fix | G3: status | H3: owner | I3: resolved_date | J3: notes
A4: 1 | B4: GP-RUBY-0001 | C4: Info | D4: all | E4: Sample row passes core lookup | F4: No action | G4: Open | J4: Generated sample
A5: 2 | B5: GP-BS-0002 | C5: Warning | D5: carat_weight | E5: Ratti provided; carat will be derived | F5: Verify conversion | G5: Open | J5: 1 ratti = 0.91 carat
A6: 3 | B6: GP-EM-0003 | C6: Warning | D6: shipping_days | E6: Shipping day 14 should be verified against business rule | F6: Confirm dispatch text | G6: Open | J6: Known source-data risk

Sheet 10_Master_Gem_Types
A1: 10_Master_Gem_Types
A2: Normalized lookup/configuration sheet. Maintain this instead of fragile helper formulas scattered across the old workbook.
A3: gem_type | B3: gemstone2 | C3: gemstone | D3: treatment | E3: cutting_style | F3: j_colour | G3: gemstone_benefits | H3: hsn_code | I3: tax_class_id | J3: gem_composition | K3: product_type | L3: origin | M3: gemstone2_type | N3: classification | O3: url_key | P3: is_active | Q3: priority | R3: notes
A4: Mozambique Ruby | B4: Mozambique Ruby | C4: Ruby | D4: Heated | E4: Faceted | F4: Vivid Red | G4: Astrological and luxury gemstone | H4: 71039120 | I4: 2 | J4: Natural | K4: Single Stone | L4: Mozambique | M4: Precious | N4: ruby | O4: ruby | P4: TRUE | Q4: 10 | R4: Sample
A5: Royal Blue Sapphire | B5: Ceylon Blue Sapphire | C5: Blue Sapphire | D5: Heated | E5: Faceted | F5: Blue (Royal Blue) | G5: Astrological premium gemstone | H5: 71039120 | I5: 2 | J5: Natural | K5: Single Stone | L5: Sri Lanka | M5: Precious | N5: blue-sapphire | O5: blue-sapphire-neelam | P5: TRUE | Q5: 10 | R5: Sample
A6: Minor Oil Emerald | B6: Zambian Emerald | C6: Emerald | D6: Minor Oil | E6: Faceted | F6: Green | G6: Astrological premium gemstone | H6: 71039120 | I6: 2 | J6: Natural | K6: Single Stone | L6: Zambia | M6: Precious | N6: emerald | O6: emerald-panna | P6: TRUE | Q6: 10 | R6: Sample
A7: Brazilian Amethyst | B7: Brazilian Amethyst | C7: Amethyst | D7: Unheated | E7: Faceted | F7: Purple | G7: Semi-precious healing gemstone | H7: 71039990 | I7: 2 | J7: Natural | K7: Single Stone | L7: Brazil | M7: Semi-Precious | N7: amethyst | O7: amethyst | P7: TRUE | Q7: 20 | R7: Sample
A8: Opal | B8: Australian Opal | C8: Opal | D8: Untreated | E8: Cabochon | F8: White | G8: Beauty and healing gemstone | H8: 71039990 | I8: 2 | J8: Natural | K8: Single Stone | L8: Australia | M8: Semi-Precious | N8: opal | O8: opal | P8: TRUE | Q8: 20 | R8: Sample

Sheet 11_Master_Gemstone2
A1: 11_Master_Gemstone2
A2: Normalized lookup/configuration sheet. Maintain this instead of fragile helper formulas scattered across the old workbook.
A3: gemstone2 | B3: gemstone | C3: default_treatment | D3: default_cutting_style | E3: default_hsn_code | F3: default_tax_class_id | G3: default_composition | H3: default_classification | I3: default_url_key | J3: gemstone2_type | K3: default_origin | L3: default_product_type | M3: notes
A4: Mozambique Ruby | B4: Ruby | C4: Heated | D4: Faceted | E4: 71039120 | F4: 2 | G4: Natural | H4: ruby | I4: ruby | J4: Precious | K4: Mozambique | L4: Single Stone | M4: Default only; final rule should use gem_type
A5: Ceylon Blue Sapphire | B5: Blue Sapphire | C5: Heated | D5: Faceted | E5: 71039120 | F5: 2 | G5: Natural | H5: blue-sapphire | I5: blue-sapphire-neelam | J5: Precious | K5: Sri Lanka | L5: Single Stone | M5: Default only
A6: Zambian Emerald | B6: Emerald | C6: Minor Oil | D6: Faceted | E6: 71039120 | F6: 2 | G6: Natural | H6: emerald | I6: emerald-panna | J6: Precious | K6: Zambia | L6: Single Stone | M6: Default only

Sheet 12_Color_Mapping
A1: 12_Color_Mapping
A2: Normalized lookup/configuration sheet. Maintain this instead of fragile helper formulas scattered across the old workbook.
A3: certificate_colour_raw | B3: j_colour | C3: display_colour | D3: google_colour | E3: vivid_normalized | F3: special_colour_name | G3: priority | H3: is_active | I3: notes
A4: Vivid Red | B4: Vivid Red (Pigeon Blood Red) | C4: Pigeon Blood Red | D4: Red | E4: Vivid Red | F4: Pigeon Blood Red | G4: 1 | H4: TRUE | I4: Premium ruby wording
A5: Royal Blue | B5: Blue (Royal Blue) | C5: Royal Blue | D5: Blue | E5: Royal Blue | F5: Royal Blue | G5: 1 | H5: TRUE | I5: Blue sapphire wording
A6: Green | B6: Green | C6: Green | D6: Green | G6: 10 | H6: TRUE | I6: Default
A7: Deep Blue | B7: Deep Blue (Royal Blue) | C7: Deep Royal Blue | D7: Blue | E7: Deep Blue | F7: Royal Blue | G7: 2 | H7: TRUE
A8: Golden Yellow | B8: Golden Yellow | C8: Golden Yellow | D8: Yellow | E8: Golden Yellow | G8: 2 | H8: TRUE

Sheet 13_Certification_Stickers
A1: 13_Certification_Stickers
A2: Normalized lookup/configuration sheet. Maintain this instead of fragile helper formulas scattered across the old workbook.
A3: certification_lab | B3: certificate_type | C3: sticker_slug | D3: display_text | E3: is_active | F3: notes
A4: IGI Certified | B4: Lab Certificate | C4: igi-certified | D4: IGI Certified | E4: TRUE
A5: GRS Certified | B5: Lab Certificate | C5: grs | D5: GRS Certified | E5: TRUE
A6: AIGS Certified | B6: Lab Certificate | C6: aigs | D6: AIGS Certified | E6: TRUE
A7: GIA Certified | B7: Lab Certificate | C7: gia-certified | D7: GIA Certified | E7: TRUE | F7: Extra cost/turnaround if requested
A8: Uncertified | B8: None | D8: Uncertified | E8: TRUE

Sheet 14_Shipping_Rules
A1: 14_Shipping_Rules
A2: Normalized lookup/configuration sheet. Maintain this instead of fragile helper formulas scattered across the old workbook.
A3: shipping_days | B3: dispatch_text | C3: jewelry_extra_days | D3: bracelet_gold_extra_days | E3: priority | F3: is_active | G3: notes
A4: 0 | B4: Ready to Ship | C4: +5 days for typical Jewellery | D4: +14 days for Bracelet/Gold/CZ/Diamond Items | E4: 1 | F4: TRUE
A5: 3 | B5: 3 Business Days | C5: +5 days for typical Jewellery | D5: +14 days for Bracelet/Gold/CZ/Diamond Items | E5: 1 | F5: TRUE
A6: 7 | B6: 7 Business Days | C6: +5 days for typical Jewellery | D6: +14 days for Bracelet/Gold/CZ/Diamond Items | E6: 1 | F6: TRUE
A7: 9 | B7: 9 Business Days | C7: +5 days for typical Jewellery | D7: +14 days for Bracelet/Gold/CZ/Diamond Items | E7: 1 | F7: TRUE
A8: 14 | B8: 9 Business Days | C8: +5 days for typical Jewellery | D8: +14 days for Bracelet/Gold/CZ/Diamond Items | E8: 99 | F8: TRUE | G8: Verify: source sheet mapped 14 to 9 business days

Sheet 15_Calibration_Rules
A1: 15_Calibration_Rules
A2: Normalized lookup/configuration sheet. Maintain this instead of fragile helper formulas scattered across the old workbook.
A3: shape_raw | B3: calibration_group | C3: min_length_mm | D3: max_length_mm | E3: min_width_mm | F3: max_width_mm | G3: calibrated_label | H3: is_active | I3: notes
A4: Oval | B4: Oval+Emerald+cushion | C4: 3 | D4: 20 | E4: 3 | F4: 15 | G4: Calibrated Oval Family | H4: TRUE
A5: Cushion | B5: Oval+Emerald+cushion | C5: 3 | D5: 20 | E5: 3 | F5: 15 | G5: Calibrated Oval Family | H5: TRUE
A6: Emerald Cut | B6: Oval+Emerald+cushion | C6: 3 | D6: 20 | E6: 3 | F6: 15 | G6: Calibrated Oval Family | H6: TRUE
A7: Round | B7: Round+Square | C7: 2 | D7: 15 | E7: 2 | F7: 15 | G7: Calibrated Round/Square | H7: TRUE | I7: Exception: pearl round may map to Pearl
A8: Pear | B8: Pear | C8: 3 | D8: 20 | E8: 2 | F8: 15 | G8: Calibrated Pear | H8: TRUE
A9: Marquise | B9: Marquise+Baguette+Rectangle | C9: 3 | D9: 25 | E9: 1 | F9: 10 | G9: Calibrated Long Shape | H9: TRUE

Sheet 16_Astro_Flags
A1: 16_Astro_Flags
A2: Normalized lookup/configuration sheet. Maintain this instead of fragile helper formulas scattered across the old workbook.
A3: gemstone | B3: astro_status | C3: consultation_required | D3: default_pitch | E3: notes
A4: Ruby | B4: Astro | C4: Yes | D4: Can be used for Sun-related astrological purposes. | E4: Premium gemstone
A5: Blue Sapphire | B5: Astro | C5: Yes | D5: Can be used for Saturn-related astrological purposes. | E5: Premium gemstone
A6: Emerald | B6: Astro | C6: Yes | D6: Can be used for Mercury-related astrological purposes. | E6: Premium gemstone
A7: Amethyst | B7: Astro | C7: Optional | D7: Often used as an alternative gemstone. | E7: Semi-precious
A8: Agate | B8: Non-Astro | C8: No | D8: Beauty/healing gemstone. | E8: Non-astro

Sheet 17_Physical_Properties
A1: 17_Physical_Properties
A2: Normalized lookup/configuration sheet. Maintain this instead of fragile helper formulas scattered across the old workbook.
A3: gemstone | B3: specific_gravity_min | C3: specific_gravity_max | D3: refractive_index_min | E3: refractive_index_max | F3: hardness_mohs | G3: notes
A4: Ruby | B4: 3.95 | C4: 4.05 | D4: 1.762 | E4: 1.77 | F4: 9 | G4: Reference values; verify lab-level exceptions
A5: Blue Sapphire | B5: 3.95 | C5: 4.05 | D5: 1.762 | E5: 1.77 | F5: 9 | G5: Corundum
A6: Emerald | B6: 2.67 | C6: 2.78 | D6: 1.565 | E6: 1.602 | F6: 7.5 | G6: Beryl
A7: Amethyst | B7: 2.63 | C7: 2.65 | D7: 1.544 | E7: 1.553 | F7: 7 | G7: Quartz
A8: Opal | B8: 1.98 | C8: 2.25 | D8: 1.37 | E8: 1.47 | F8: 6 | G8: Hydrated silica

Sheet 18_Valid_Values
A1: 18_Valid_Values
A2: Normalized lookup/configuration sheet. Maintain this instead of fragile helper formulas scattered across the old workbook.
A3: category | B3: value | C3: is_active | D3: notes
A4: product_type | B4: Single Stone | C4: TRUE
A5: product_type | B5: Pair | C5: TRUE
A6: product_type | B6: Set | C6: TRUE
A7: product_type | B7: Beads | C7: TRUE
A8: product_type | B8: Carving | C8: TRUE
A9: product_type | B9: Rough | C9: TRUE
A10: product_type | B10: Jewellery | C10: TRUE
A11: stock_status | B11: In Stock | C11: TRUE
A12: stock_status | B12: Sold Out | C12: TRUE
A13: stock_status | B13: Reserved | C13: TRUE
A14: stock_status | B14: Draft | C14: TRUE
A15: stock_status | B15: Disabled | C15: TRUE
... A45: manual_review_reason | B45: Shipping rule missing | C45: TRUE

Sheet 19_Naming_Rules
A1: 19_Naming_Rules
